Exception on /search [POST]
Traceback (most recent call last):
  File "/home/ing/PycharmProjects/geo-geschenk/geo-geschenk/virtualenv/lib/python3.3/site-packages/flask/app.py", line 1817, in wsgi_app
    response = self.full_dispatch_request()
  File "/home/ing/PycharmProjects/geo-geschenk/geo-geschenk/virtualenv/lib/python3.3/site-packages/flask/app.py", line 1477, in full_dispatch_request
    rv = self.handle_user_exception(e)
  File "/home/ing/PycharmProjects/geo-geschenk/geo-geschenk/virtualenv/lib/python3.3/site-packages/flask/app.py", line 1381, in handle_user_exception
    reraise(exc_type, exc_value, tb)
  File "/home/ing/PycharmProjects/geo-geschenk/geo-geschenk/virtualenv/lib/python3.3/site-packages/flask/_compat.py", line 33, in reraise
    raise value
  File "/home/ing/PycharmProjects/geo-geschenk/geo-geschenk/virtualenv/lib/python3.3/site-packages/flask/app.py", line 1475, in full_dispatch_request
    rv = self.dispatch_request()
  File "/home/ing/PycharmProjects/geo-geschenk/geo-geschenk/virtualenv/lib/python3.3/site-packages/flask/app.py", line 1461, in dispatch_request
    return self.view_functions[rule.endpoint](**req.view_args)
  File "app/main.py", line 48, in search
    return make_response(loads(dumps(res)))
  File "/home/ing/PycharmProjects/geo-geschenk/geo-geschenk/virtualenv/lib/python3.3/site-packages/flask/helpers.py", line 183, in make_response
    return current_app.make_response(args)
  File "/home/ing/PycharmProjects/geo-geschenk/geo-geschenk/virtualenv/lib/python3.3/site-packages/flask/app.py", line 1577, in make_response
    rv = self.response_class.force_type(rv, request.environ)
  File "/home/ing/PycharmProjects/geo-geschenk/geo-geschenk/virtualenv/lib/python3.3/site-packages/werkzeug/wrappers.py", line 847, in force_type
    response = BaseResponse(*_run_wsgi_app(response, environ))
  File "/home/ing/PycharmProjects/geo-geschenk/geo-geschenk/virtualenv/lib/python3.3/site-packages/werkzeug/test.py", line 871, in run_wsgi_app
    app_rv = app(environ, start_response)
TypeError: 'dict' object is not callable
Exception on /search [POST]
Traceback (most recent call last):
  File "/home/ing/PycharmProjects/geo-geschenk/geo-geschenk/virtualenv/lib/python3.3/site-packages/flask/app.py", line 1817, in wsgi_app
    response = self.full_dispatch_request()
  File "/home/ing/PycharmProjects/geo-geschenk/geo-geschenk/virtualenv/lib/python3.3/site-packages/flask/app.py", line 1477, in full_dispatch_request
    rv = self.handle_user_exception(e)
  File "/home/ing/PycharmProjects/geo-geschenk/geo-geschenk/virtualenv/lib/python3.3/site-packages/flask/app.py", line 1381, in handle_user_exception
    reraise(exc_type, exc_value, tb)
  File "/home/ing/PycharmProjects/geo-geschenk/geo-geschenk/virtualenv/lib/python3.3/site-packages/flask/_compat.py", line 33, in reraise
    raise value
  File "/home/ing/PycharmProjects/geo-geschenk/geo-geschenk/virtualenv/lib/python3.3/site-packages/flask/app.py", line 1475, in full_dispatch_request
    rv = self.dispatch_request()
  File "/home/ing/PycharmProjects/geo-geschenk/geo-geschenk/virtualenv/lib/python3.3/site-packages/flask/app.py", line 1461, in dispatch_request
    return self.view_functions[rule.endpoint](**req.view_args)
  File "app/main.py", line 48, in search
    return make_response(jsonify(dumps(res)))
  File "/home/ing/PycharmProjects/geo-geschenk/geo-geschenk/virtualenv/lib/python3.3/site-packages/flask/json.py", line 237, in jsonify
    return current_app.response_class(dumps(dict(*args, **kwargs),
ValueError: dictionary update sequence element #0 has length 1; 2 is required
Exception on /search [POST]
Traceback (most recent call last):
  File "/home/ing/PycharmProjects/geo-geschenk/geo-geschenk/virtualenv/lib/python3.3/site-packages/flask/app.py", line 1817, in wsgi_app
    response = self.full_dispatch_request()
  File "/home/ing/PycharmProjects/geo-geschenk/geo-geschenk/virtualenv/lib/python3.3/site-packages/flask/app.py", line 1477, in full_dispatch_request
    rv = self.handle_user_exception(e)
  File "/home/ing/PycharmProjects/geo-geschenk/geo-geschenk/virtualenv/lib/python3.3/site-packages/flask/app.py", line 1381, in handle_user_exception
    reraise(exc_type, exc_value, tb)
  File "/home/ing/PycharmProjects/geo-geschenk/geo-geschenk/virtualenv/lib/python3.3/site-packages/flask/_compat.py", line 33, in reraise
    raise value
  File "/home/ing/PycharmProjects/geo-geschenk/geo-geschenk/virtualenv/lib/python3.3/site-packages/flask/app.py", line 1475, in full_dispatch_request
    rv = self.dispatch_request()
  File "/home/ing/PycharmProjects/geo-geschenk/geo-geschenk/virtualenv/lib/python3.3/site-packages/flask/app.py", line 1461, in dispatch_request
    return self.view_functions[rule.endpoint](**req.view_args)
  File "app/main.py", line 48, in search
    return make_response(jsonify(dumps(res)))
  File "/home/ing/PycharmProjects/geo-geschenk/geo-geschenk/virtualenv/lib/python3.3/site-packages/flask/json.py", line 237, in jsonify
    return current_app.response_class(dumps(dict(*args, **kwargs),
ValueError: dictionary update sequence element #0 has length 1; 2 is required
Exception on /search [POST]
Traceback (most recent call last):
  File "/home/ing/PycharmProjects/geo-geschenk/geo-geschenk/virtualenv/lib/python3.3/site-packages/flask/app.py", line 1817, in wsgi_app
    response = self.full_dispatch_request()
  File "/home/ing/PycharmProjects/geo-geschenk/geo-geschenk/virtualenv/lib/python3.3/site-packages/flask/app.py", line 1477, in full_dispatch_request
    rv = self.handle_user_exception(e)
  File "/home/ing/PycharmProjects/geo-geschenk/geo-geschenk/virtualenv/lib/python3.3/site-packages/flask/app.py", line 1381, in handle_user_exception
    reraise(exc_type, exc_value, tb)
  File "/home/ing/PycharmProjects/geo-geschenk/geo-geschenk/virtualenv/lib/python3.3/site-packages/flask/_compat.py", line 33, in reraise
    raise value
  File "/home/ing/PycharmProjects/geo-geschenk/geo-geschenk/virtualenv/lib/python3.3/site-packages/flask/app.py", line 1475, in full_dispatch_request
    rv = self.dispatch_request()
  File "/home/ing/PycharmProjects/geo-geschenk/geo-geschenk/virtualenv/lib/python3.3/site-packages/flask/app.py", line 1461, in dispatch_request
    return self.view_functions[rule.endpoint](**req.view_args)
  File "app/main.py", line 50, in search
    two = jsonify(one)
  File "/home/ing/PycharmProjects/geo-geschenk/geo-geschenk/virtualenv/lib/python3.3/site-packages/flask/json.py", line 237, in jsonify
    return current_app.response_class(dumps(dict(*args, **kwargs),
ValueError: dictionary update sequence element #0 has length 1; 2 is required
Exception on /search [POST]
Traceback (most recent call last):
  File "/home/ing/PycharmProjects/geo-geschenk/geo-geschenk/virtualenv/lib/python3.3/site-packages/flask/app.py", line 1817, in wsgi_app
    response = self.full_dispatch_request()
  File "/home/ing/PycharmProjects/geo-geschenk/geo-geschenk/virtualenv/lib/python3.3/site-packages/flask/app.py", line 1477, in full_dispatch_request
    rv = self.handle_user_exception(e)
  File "/home/ing/PycharmProjects/geo-geschenk/geo-geschenk/virtualenv/lib/python3.3/site-packages/flask/app.py", line 1381, in handle_user_exception
    reraise(exc_type, exc_value, tb)
  File "/home/ing/PycharmProjects/geo-geschenk/geo-geschenk/virtualenv/lib/python3.3/site-packages/flask/_compat.py", line 33, in reraise
    raise value
  File "/home/ing/PycharmProjects/geo-geschenk/geo-geschenk/virtualenv/lib/python3.3/site-packages/flask/app.py", line 1475, in full_dispatch_request
    rv = self.dispatch_request()
  File "/home/ing/PycharmProjects/geo-geschenk/geo-geschenk/virtualenv/lib/python3.3/site-packages/flask/app.py", line 1461, in dispatch_request
    return self.view_functions[rule.endpoint](**req.view_args)
  File "app/main.py", line 50, in search
    two = jsonify(one)
  File "/home/ing/PycharmProjects/geo-geschenk/geo-geschenk/virtualenv/lib/python3.3/site-packages/flask/json.py", line 237, in jsonify
    return current_app.response_class(dumps(dict(*args, **kwargs),
ValueError: dictionary update sequence element #0 has length 1; 2 is required
